Workbook

Sheet Participantes
A1: 🏆 QUINIELA MUNDIAL 2026
A2: Acierto único = 3 pts | Acierto compartido (2 o más) = 1 pt cada uno | Sin acierto = 0 pts
A4: # | B4: Participante | C4: Puntos | D4: Posición
A5: 1 | B5: Andres Jesús | C5: 0 | D5: =RANK(C5,C5:C19,0) -> 1
A6: 2 | B6: Leonardo Fabio | C6: 0 | D6: =RANK(C6,C5:C19,0) -> 1
A7: 3 | B7: Martha Cenidia | C7: 0 | D7: =RANK(C7,C5:C19,0) -> 1
A8: 4 | B8: Freddy Ramón | C8: 0 | D8: =RANK(C8,C5:C19,0) -> 1
A9: 5 | B9: Juan Camilo | C9: 0 | D9: =RANK(C9,C5:C19,0) -> 1
A10: 6 | B10: Juan David | C10: 0 | D10: =RANK(C10,C5:C19,0) -> 1
A11: 7 | B11: María Trinidad | C11: 0 | D11: =RANK(C11,C5:C19,0) -> 1
A12: 8 | B12: María Gabriela | C12: 0 | D12: =RANK(C12,C5:C19,0) -> 1
A13: 9 | B13: Laura Valentina | C13: 0 | D13: =RANK(C13,C5:C19,0) -> 1
A14: 10 | B14: Gloria Isabel | C14: 0 | D14: =RANK(C14,C5:C19,0) -> 1
A15: 11 | B15: María del Pilar | C15: 0 | D15: =RANK(C15,C5:C19,0) -> 1
A16: 12 | B16: Jaime Andres | C16: 0 | D16: =RANK(C16,C5:C19,0) -> 1
A17: 13 | B17: Participante 13 | C17: 0 | D17: =RANK(C17,C5:C19,0) -> 1
A18: 14 | B18: Participante 14 | C18: 0 | D18: =RANK(C18,C5:C19,0) -> 1
A19: 15 | B19: Participante 15 | C19: 0 | D19: =RANK(C19,C5:C19,0) -> 1

Sheet Fixture
A1: ⚽ FIXTURE FASE DE GRUPOS — FIFA WORLD CUP 2026
A2: Ingresa el resultado oficial en las columnas verdes después de cada partido
A4: # | B4: Grupo | C4: Local | D4: Goles Local | E4: Goles Visitante | F4: Visitante | G4: Fecha
A5: 1 | B5: A | C5: México | D5: 2 | E5: 0 | F5: Sudáfrica | G5: 11 jun
A6: 2 | B6: A | C6: Corea del Sur | D6: 2 | E6: 1 | F6: Chequia | G6: 11 jun
A7: 3 | B7: A | C7: Chequia | F7: Sudáfrica | G7: 18 jun
A8: 4 | B8: A | C8: México | F8: Corea del Sur | G8: 18 jun
A9: 5 | B9: A | C9: Chequia | F9: México | G9: 24 jun
A10: 6 | B10: A | C10: Sudáfrica | F10: Corea del Sur | G10: 24 jun
A11: 7 | B11: B | C11: Canadá | D11: 1 | E11: 1 | F11: Bosnia-Herzegovina | G11: 12 jun
A12: 8 | B12: B | C12: Qatar | D12: 1 | E12: 1 | F12: Suiza | G12: 13 jun
A13: 9 | B13: B | C13: Suiza | F13: Bosnia-Herzegovina | G13: 18 jun
A14: 10 | B14: B | C14: Canadá | F14: Qatar | G14: 18 jun
A15: 11 | B15: B | C15: Suiza | F15: Canadá | G15: 24 jun
A16: 12 | B16: B | C16: Bosnia-Herzegovina | F16: Qatar | G16: 24 jun
A17: 13 | B17: C | C17: Brasil | D17: 1 | E17: 1 | F17: Marruecos | G17: 13 jun
A18: 14 | B18: C | C18: Haití | D18: 0 | E18: 1 | F18: Escocia | G18: 13 jun
A19: 15 | B19: C | C19: Escocia | F19: Marruecos | G19: 19 jun
A20: 16 | B20: C | C20: Brasil | F20: Haití | G20: 19 jun
A21: 17 | B21: C | C21: Escocia | F21: Brasil | G21: 24 jun
A22: 18 | B22: C | C22: Marruecos | F22: Haití | G22: 24 jun
A23: 19 | B23: D | C23: Estados Unidos | D23: 4 | E23: 1 | F23: Paraguay | G23: 12 jun
A24: 20 | B24: D | C24: Australia | D24: 2 | E24: 0 | F24: Turquía | G24: 13 jun
A25: 21 | B25: D | C25: Estados Unidos | F25: Australia | G25: 19 jun
A26: 22 | B26: D | C26: Turquía | F26: Paraguay | G26: 19 jun
A27: 23 | B27: D | C27: Turquía | F27: Estados Unidos | G27: 25 jun
A28: 24 | B28: D | C28: Paraguay | F28: Australia | G28: 25 jun
A29: 25 | B29: E | C29: Alemania | F29: Curazao | G29: 14 jun
A30: 26 | B30: E | C30: Costa de Marfil | F30: Ecuador | G30: 14 jun
A31: 27 | B31: E | C31: Alemania | F31: Costa de Marfil | G31: 20 jun
A32: 28 | B32: E | C32: Ecuador | F32: Curazao | G32: 20 jun
A33: 29 | B33: E | C33: Ecuador | F33: Alemania | G33: 25 jun
A34: 30 | B34: E | C34: Curazao | F34: Costa de Marfil | G34: 25 jun
A35: 31 | B35: F | C35: Países Bajos | F35: Japón | G35: 14 jun
A36: 32 | B36: F | C36: Suecia | F36: Túnez | G36: 14 jun
... A76: 72 | B76: L | C76: Croacia | F76: Ghana | G76: 27 jun

Sheet Predicciones
A1: 🎯 PREDICCIONES — FASE DE GRUPOS MUNDIAL 2026
A2: Ingresa el marcador que predices (L = Goles Local | V = Goles Visitante)
A4: # | B4: Partido | C4: Resultado Real | D4: =Participantes!B5 -> Andres Jesús | F4: =Participantes!B6 -> Leonardo Fabio | H4: =Participantes!B7 -> Martha Cenidia | J4: =Participantes!B8 -> Freddy Ramón | L4: =Participantes!B9 -> Juan Camilo | N4: =Participantes!B10 -> Juan David | P4: =Participantes!B11 -> María Trinidad | R4: =Participantes!B12 -> María Gabriela | T4: =Participantes!B13 -> Laura Valentina | V4: =Participantes!B14 -> Gloria Isabel | X4: =Participantes!B15 -> María del Pilar | Z4: =Participantes!B16 -> Jaime Andres | AB4: =Participantes!B17 -> Participante 13 | AD4: =Participantes!B18 -> Participante 14 | AF4: =Participantes!B19 -> Participante 15
C5: L – V | D5: L | E5: V | F5: L | G5: V | H5: L | I5: V | J5: L | K5: V | L5: L | M5: V | N5: L | O5: V | P5: L | Q5: V | R5: L | S5: V | T5: L | U5: V | V5: L | W5: V | X5: L | Y5: V | Z5: L | AA5: V | AB5: L | AC5: V | AD5: L | AE5: V | AF5: L | AG5: V
A6: 1 | B6: =Fixture!C5&" vs "&Fixture!F5 -> México vs Sudáfrica | C6: =IF(ISNUMBER(Fixture!D5),Fixture!D5&"-"&Fixture!E5,"") -> 2-0 | D6: 2 | E6: 1 | F6: 1 | G6: 1 | H6: 3 | I6: 0 | J6: 2 | K6: 0 | L6: 3 | M6: 1 | N6: 3 | O6: 1 | P6: 4 | Q6: 1 | R6: 2 | S6: 1 | T6: 2 | U6: 1 | V6: 3 | W6: 0 | X6: 2 | Y6: 0 | Z6: 2 | AA6: 1
A7: 2 | B7: =Fixture!C6&" vs "&Fixture!F6 -> Corea del Sur vs Chequia | C7: =IF(ISNUMBER(Fixture!D6),Fixture!D6&"-"&Fixture!E6,"") -> 2-1 | D7: 1 | E7: 3 | F7: 1 | G7: 1 | H7: 1 | I7: 2 | J7: 2 | K7: 2 | L7: 1 | M7: 0 | N7: 1 | O7: 1 | P7: 2 | Q7: 0 | R7: 1 | S7: 0 | T7: 1 | U7: 1 | V7: 0 | W7: 0 | X7: 2 | Y7: 1 | Z7: 2 | AA7: 0
A8: 3 | B8: =Fixture!C7&" vs "&Fixture!F7 -> Chequia vs Sudáfrica | C8: =IF(ISNUMBER(Fixture!D7),Fixture!D7&"-"&Fixture!E7,"")
A9: 4 | B9: =Fixture!C8&" vs "&Fixture!F8 -> México vs Corea del Sur | C9: =IF(ISNUMBER(Fixture!D8),Fixture!D8&"-"&Fixture!E8,"")
A10: 5 | B10: =Fixture!C9&" vs "&Fixture!F9 -> Chequia vs México | C10: =IF(ISNUMBER(Fixture!D9),Fixture!D9&"-"&Fixture!E9,"")
A11: 6 | B11: =Fixture!C10&" vs "&Fixture!F10 -> Sudáfrica vs Corea del Sur | C11: =IF(ISNUMBER(Fixture!D10),Fixture!D10&"-"&Fixture!E10,"")
A12: 7 | B12: =Fixture!C11&" vs "&Fixture!F11 -> Canadá vs Bosnia-Herzegovina | C12: =IF(ISNUMBER(Fixture!D11),Fixture!D11&"-"&Fixture!E11,"") -> 1-1 | D12: 0 | E12: 2 | F12: 2 | G12: 0 | H12: 2 | I12: 2 | J12: 1 | K12: 1 | L12: 2 | M12: 0 | N12: 1 | O12: 1 | P12: 1 | Q12: 0 | R12: 1 | S12: 0 | T12: 1 | U12: 0 | V12: 1 | W12: 1 | X12: 1 | Y12: 1 | Z12: 2 | AA12: 0
A13: 8 | B13: =Fixture!C12&" vs "&Fixture!F12 -> Qatar vs Suiza | C13: =IF(ISNUMBER(Fixture!D12),Fixture!D12&"-"&Fixture!E12,"") -> 1-1 | D13: 0 | E13: 2 | F13: 0 | G13: 2 | H13: 0 | I13: 2 | J13: 2 | K13: 1 | L13: 0 | M13: 3 | N13: 0 | O13: 2 | T13: 0 | U13: 2 | V13: 1 | W13: 2 | X13: 0 | Y13: 3
A14: 9 | B14: =Fixture!C13&" vs "&Fixture!F13 -> Suiza vs Bosnia-Herzegovina | C14: =IF(ISNUMBER(Fixture!D13),Fixture!D13&"-"&Fixture!E13,"")
A15: 10 | B15: =Fixture!C14&" vs "&Fixture!F14 -> Canadá vs Qatar | C15: =IF(ISNUMBER(Fixture!D14),Fixture!D14&"-"&Fixture!E14,"")
A16: 11 | B16: =Fixture!C15&" vs "&Fixture!F15 -> Suiza vs Canadá | C16: =IF(ISNUMBER(Fixture!D15),Fixture!D15&"-"&Fixture!E15,"")
A17: 12 | B17: =Fixture!C16&" vs "&Fixture!F16 -> Bosnia-Herzegovina vs Qatar | C17: =IF(ISNUMBER(Fixture!D16),Fixture!D16&"-"&Fixture!E16,"")
A18: 13 | B18: =Fixture!C17&" vs "&Fixture!F17 -> Brasil vs Marruecos | C18: =IF(ISNUMBER(Fixture!D17),Fixture!D17&"-"&Fixture!E17,"") -> 1-1 | D18: 1 | E18: 1 | F18: 1 | G18: 0 | H18: 2 | I18: 1 | J18: 2 | K18: 2 | L18: 2 | M18: 1 | N18: 2 | O18: 1 | P18: 3 | Q18: 1 | T18: 2 | U18: 1 | V18: 2 | W18: 2 | X18: 2 | Y18: 1 | Z18: 2 | AA18: 0
A19: 14 | B19: =Fixture!C18&" vs "&Fixture!F18 -> Haití vs Escocia | C19: =IF(ISNUMBER(Fixture!D18),Fixture!D18&"-"&Fixture!E18,"") -> 0-1 | D19: 0 | E19: 2 | F19: 1 | G19: 2 | H19: 0 | I19: 2 | J19: 0 | K19: 4 | L19: 0 | M19: 2 | N19: 0 | O19: 3 | P19: 1 | Q19: 1 | T19: 0 | U19: 2 | V19: 0 | W19: 2 | X19: 1 | Y19: 3 | Z19: 1 | AA19: 1
A20: 15 | B20: =Fixture!C19&" vs "&Fixture!F19 -> Escocia vs Marruecos | C20: =IF(ISNUMBER(Fixture!D19),Fixture!D19&"-"&Fixture!E19,"")
A21: 16 | B21: =Fixture!C20&" vs "&Fixture!F20 -> Brasil vs Haití | C21: =IF(ISNUMBER(Fixture!D20),Fixture!D20&"-"&Fixture!E20,"")
A22: 17 | B22: =Fixture!C21&" vs "&Fixture!F21 -> Escocia vs Brasil | C22: =IF(ISNUMBER(Fixture!D21),Fixture!D21&"-"&Fixture!E21,"")
A23: 18 | B23: =Fixture!C22&" vs "&Fixture!F22 -> Marruecos vs Haití | C23: =IF(ISNUMBER(Fixture!D22),Fixture!D22&"-"&Fixture!E22,"")
A24: 19 | B24: =Fixture!C23&" vs "&Fixture!F23 -> Estados Unidos vs Paraguay | C24: =IF(ISNUMBER(Fixture!D23),Fixture!D23&"-"&Fixture!E23,"") -> 4-1 | D24: 2 | E24: 0 | F24: 0 | G24: 1 | H24: 1 | I24: 0 | J24: 3 | K24: 1 | L24: 1 | M24: 2 | N24: 1 | O24: 2 | P24: 1 | Q24: 1 | R24: 2 | S24: 1 | T24: 2 | U24: 1 | V24: 1 | W24: 1 | X24: 2 | Y24: 1 | Z24: 2 | AA24: 1
A25: 20 | B25: =Fixture!C24&" vs "&Fixture!F24 -> Australia vs Turquía | C25: =IF(ISNUMBER(Fixture!D24),Fixture!D24&"-"&Fixture!E24,"") -> 2-0 | D25: 1 | E25: 2 | F25: 1 | G25: 1 | H25: 1 | I25: 1 | J25: 0 | K25: 2 | L25: 1 | M25: 1 | N25: 1 | O25: 3 | P25: 1 | Q25: 2 | T25: 1 | U25: 2 | V25: 1 | W25: 2 | X25: 1 | Y25: 1
A26: 21 | B26: =Fixture!C25&" vs "&Fixture!F25 -> Estados Unidos vs Australia | C26: =IF(ISNUMBER(Fixture!D25),Fixture!D25&"-"&Fixture!E25,"")
A27: 22 | B27: =Fixture!C26&" vs "&Fixture!F26 -> Turquía vs Paraguay | C27: =IF(ISNUMBER(Fixture!D26),Fixture!D26&"-"&Fixture!E26,"")
A28: 23 | B28: =Fixture!C27&" vs "&Fixture!F27 -> Turquía vs Estados Unidos | C28: =IF(ISNUMBER(Fixture!D27),Fixture!D27&"-"&Fixture!E27,"")
A29: 24 | B29: =Fixture!C28&" vs "&Fixture!F28 -> Paraguay vs Australia | C29: =IF(ISNUMBER(Fixture!D28),Fixture!D28&"-"&Fixture!E28,"")
A30: 25 | B30: =Fixture!C29&" vs "&Fixture!F29 -> Alemania vs Curazao | C30: =IF(ISNUMBER(Fixture!D29),Fixture!D29&"-"&Fixture!E29,"") | D30: 5 | E30: 0 | F30: 3 | G30: 0 | H30: 7 | I30: 0 | J30: 6 | K30: 0 | L30: 4 | M30: 0 | N30: 6 | O30: 0 | P30: 2 | Q30: 0 | V30: 4 | W30: 0 | X30: 4 | Y30: 0
A31: 26 | B31: =Fixture!C30&" vs "&Fixture!F30 -> Costa de Marfil vs Ecuador | C31: =IF(ISNUMBER(Fixture!D30),Fixture!D30&"-"&Fixture!E30,"") | D31: 1 | E31: 1 | F31: 1 | G31: 3 | H31: 2 | I31: 2 | J31: 0 | K31: 2 | N31: 0 | O31: 1 | P31: 1 | Q31: 1 | V31: 1 | W31: 1 | X31: 2 | Y31: 1
A32: 27 | B32: =Fixture!C31&" vs "&Fixture!F31 -> Alemania vs Costa de Marfil | C32: =IF(ISNUMBER(Fixture!D31),Fixture!D31&"-"&Fixture!E31,"")
A33: 28 | B33: =Fixture!C32&" vs "&Fixture!F32 -> Ecuador vs Curazao | C33: =IF(ISNUMBER(Fixture!D32),Fixture!D32&"-"&Fixture!E32,"")
A34: 29 | B34: =Fixture!C33&" vs "&Fixture!F33 -> Ecuador vs Alemania | C34: =IF(ISNUMBER(Fixture!D33),Fixture!D33&"-"&Fixture!E33,"")
A35: 30 | B35: =Fixture!C34&" vs "&Fixture!F34 -> Curazao vs Costa de Marfil | C35: =IF(ISNUMBER(Fixture!D34),Fixture!D34&"-"&Fixture!E34,"")
A36: 31 | B36: =Fixture!C35&" vs "&Fixture!F35 -> Países Bajos vs Japón | C36: =IF(ISNUMBER(Fixture!D35),Fixture!D35&"-"&Fixture!E35,"") | D36: 2 | E36: 2 | F36: 2 | G36: 2 | H36: 1 | I36: 1 | J36: 3 | K36: 2 | L36: 1 | M36: 1 | N36: 2 | O36: 1 | P36: 1 | Q36: 2 | V36: 2 | W36: 2 | X36: 1 | Y36: 1
A37: 32 | B37: =Fixture!C36&" vs "&Fixture!F36 -> Suecia vs Túnez | C37: =IF(ISNUMBER(Fixture!D36),Fixture!D36&"-"&Fixture!E36,"") | D37: 2 | E37: 0 | F37: 2 | G37: 1 | H37: 1 | I37: 1 | J37: 1 | K37: 0 | N37: 2 | O37: 0 | P37: 2 | Q37: 1 | V37: 2 | W37: 0 | X37: 2 | Y37: 0
A38: 33 | B38: =Fixture!C37&" vs "&Fixture!F37 -> Países Bajos vs Suecia | C38: =IF(ISNUMBER(Fixture!D37),Fixture!D37&"-"&Fixture!E37,"")
A39: 34 | B39: =Fixture!C38&" vs "&Fixture!F38 -> Túnez vs Japón | C39: =IF(ISNUMBER(Fixture!D38),Fixture!D38&"-"&Fixture!E38,"")
A40: 35 | B40: =Fixture!C39&" vs "&Fixture!F39 -> Japón vs Suecia | C40: =IF(ISNUMBER(Fixture!D39),Fixture!D39&"-"&Fixture!E39,"")
A41: 36 | B41: =Fixture!C40&" vs "&Fixture!F40 -> Túnez vs Países Bajos | C41: =IF(ISNUMBER(Fixture!D40),Fixture!D40&"-"&Fixture!E40,"")
...
